<?xml version="1.0" encoding="utf-8"?>
<!-- =================================================================================== -->
<!-- |    This document was autogenerated by xacro from indy7.xacro                    | -->
<!-- |    EDITING THIS FILE BY HAND IS NOT RECOMMENDED                                 | -->
<!-- =================================================================================== -->
<robot name="indy7" xmlns:xacro="http://ros.org/wiki/xacro">
  <material name="black">
    <color rgba="0.0 0.0 0.0 1.0"/>
  </material>
  <material name="blue">
    <color rgba="0.0 0.0 0.8 1.0"/>
  </material>
  <material name="green">
    <color rgba="0.0 0.8 0.0 1.0"/>
  </material>
  <material name="grey_">
    <color rgba="0.2 0.2 0.2 1.0"/>
  </material>
  <material name="orange">
    <color rgba="1.0 0.423529411765 0.0392156862745 1.0"/>
  </material>
  <material name="brown">
    <color rgba="0.870588235294 0.811764705882 0.764705882353 1.0"/>
  </material>
  <material name="red">
    <color rgba="0.8 0.0 0.0 1.0"/>
  </material>
  <material name="white">
    <color rgba="1.0 1.0 1.0 1.0"/>
  </material>
  <material name="metal">
    <color rgba="0.768627450980392 0.749019607843137 0.729411764705882 1"/>
  </material>
  <material name="metal_grey">
    <color rgba="0.501960784313725 0.501960784313725 0.501960784313725 1"/>
  </material>
  <material name="metal_white">
    <color rgba="0.866666666666667 0.866666666666667 0.890196078431373 1"/>
  </material>
  <!-- <material name="grey">
		<color rgba="0.5 0.5 0.5 1"/>
   	</material> -->
  <link name="base_link"/>
    <visual>
      <origin rpy="0 0 0" xyz="0 0 0"/>
    </visual>
    <collision>
      <origin rpy="0 0 0" xyz="0 0 0"/>
    </collision>
  <link name="link0">
    <visual>
      <origin rpy="-90 -54.57 -90" xyz="0.153010 0.10852 0.031144"/>
      <geometry>
        <mesh filename="package://indy7_description/meshes/stl/Indy7_0.stl"/>
      </geometry>
      <material name="metal_grey"/>
    </visual>
    <collision>
      <origin rpy="-90 -54.57 -90" xyz="0.153010 0.10852 0.031144"/>
      <geometry>
        <mesh filename="package://indy7_description/meshes/stl/Indy7_0.stl"/>
      </geometry>
    </collision>
    <inertial>
      <origin rpy="0 0 0" xyz="0 0 0"/>
      <mass value="1.59306955"/>
      <inertia ixx="+0.00572623" ixy="+0.00000251" ixz="-0.00011380" iyy="+0.00558959" iyz="-0.00000014" izz="+0.00966674"/>
    </inertial>
  </link>
  <link name="link1">
    <visual>
      <origin rpy="3.0217 5.0569 166.8" xyz="0.16945 0.076818 0.22458"/>
      <geometry>
        <mesh filename="package://indy7_description/meshes/stl/Indy7_1.stl"/>
      </geometry>
      <material name="metal_grey"/>
    </visual>
    <collision>
      <origin rpy="3.0217 5.0569 166.8" xyz="0.16945 0.076818 0.22458"/>
      <geometry>
        <mesh filename="package://indy7_description/meshes/stl/Indy7_1.stl"/>
      </geometry>
    </collision>
    <inertial>
      <origin rpy="0 0 0" xyz="0 0 0"/>
      <mass value="1.59306955"/>
      <inertia ixx="+0.15418559" ixy="-0.00000235" ixz="+0.00001739" iyy="+0.12937017" iyz="-0.04854267" izz="+0.05964415"/>
    </inertial>
  </link>
  <link name="link2">
    <visual>
      <origin rpy="-4.787 -0.5111 -172.8" xyz="0.16325 -0.0746 0.51878"/>
      <geometry>
        <mesh filename="package://indy7_description/meshes/stl/Indy7_2.stl"/>
      </geometry>
      <material name="metal_grey"/>
    </visual>
    <collision>
      <origin rpy="-4.787 -0.5111 -172.8" xyz="0.16325 -0.0746 0.51878"/>
      <geometry>
        <mesh filename="package://indy7_description/meshes/stl/Indy7_2.stl"/>
      </geometry>
    </collision>
    <inertial>
      <origin rpy="0 0 0" xyz="0 0 0"/>
      <mass value="0.18"/>
      <inertia ixx="+0.29356980" ixy="-0.00000040" ixz="+0.00001441" iyy="+0.25088420" iyz="+0.03727972" izz="+0.03620519"/>
    </inertial>
  </link>
  <link name="link3">
    <visual>
      <origin rpy="-0.2719 0.58253 -179.86" xyz="0.16708 0.091599 0.85707"/>
      <geometry>
        <mesh filename="package://indy7_description/meshes/stl/Indy7_3.stl"/>
      </geometry>
      <material name="metal_grey"/>
    </visual>
    <collision>
      <origin rpy="-0.2719 0.58253 -179.86" xyz="0.16708 0.091599 0.85707"/>
      <geometry>
        <mesh filename="package://indy7_description/meshes/stl/Indy7_3.stl"/>
      </geometry>
    </collision>
    <inertial>
      <origin rpy="0 0 0" xyz="0 0 0"/>
      <mass value="0.18"/>
      <inertia ixx="+0.03424593" ixy="+0.00000149" ixz="+0.00000724" iyy="+0.03406024" iyz="+0.00186009" izz="+0.00450477"/>
    </inertial>
  </link>
  <link name="link4">
    <visual>
      <origin rpy="-88.066 -0.30702 -1.5232" xyz="0.16676 0.070165 1.0815"/>
      <geometry>
        <mesh filename="package://indy7_description/meshes/stl/Indy7_4.stl"/>
      </geometry>
      <material name="metal_grey"/>
    </visual>
    <collision>
      <origin rpy="-88.066 -0.30702 -1.5232" xyz="0.16676 0.070165 1.0815"/>
      <geometry>
        <mesh filename="package://indy7_description/meshes/stl/Indy7_4.stl"/>
      </geometry>
    </collision>
    <inertial>
      <origin rpy="0 0 0" xyz="0 0 0"/>
      <mass value="0.18"/>
      <inertia ixx="+0.00670405" ixy="+0.00000375" ixz="+0.00000150" iyy="+0.00670405" iyz="-0.00127967" izz="+0.00617624"/>
    </inertial>
  </link>
  <link name="link5">
    <visual>
      <origin rpy="-2.3601 -5.0717 -80.092" xyz="0.16663 -0.072208 1.1605"/>
      <geometry>
        <mesh filename="package://indy7_description/meshes/stl/Indy7_5.stl"/>
      </geometry>
      <material name="metal_grey"/>
    </visual>
    <collision>
      <origin rpy="-2.3601 -5.0717 -80.092" xyz="0.16663 -0.072208 1.1605"/>
      <geometry>
        <mesh filename="package://indy7_description/meshes/stl/Indy7_5.stl"/>
      </geometry>
    </collision>
    <inertial>
      <origin rpy="0 0 0" xyz="0 0 0"/>
      <mass value="0.18"/>
      <inertia ixx="+0.00994891" ixy="+0.00000014" ixz="+0.00000321" iyy="+0.00978189" iyz="-0.00093546" izz="+0.00271492"/>
    </inertial>
  </link>
  <link name="link6">
    <visual>
      <origin rpy="-89.021 -29.906 90.252" xyz="0.16589 -0.079642 1.2995"/>
      <geometry>
        <mesh filename="package://indy7_description/meshes/stl/Indy7_6.stl"/>
      </geometry>
      <material name="metal_grey"/>
    </visual>
    <collision>
      <origin rpy="-89.021 -29.906 90.252" xyz="0.16589 -0.079642 1.2995"/>
      <geometry>
        <mesh filename="package://indy7_description/meshes/stl/Indy7_6.stl"/>
      </geometry>
    </collision>
    <inertial>
      <origin rpy="0 0 0" xyz="0 0 0"/>
      <mass value="0.18"/>
      <inertia ixx="0.00043534" ixy="+0.00000013" ixz="-0.00000002" iyy="0.00044549" iyz="+0.00000051" izz="0.00059634"/>
    </inertial>
  </link>
  <link name="tcp"/>
  <joint name="global" type="fixed">
    <parent link="base_link"/>
    <child link="link0"/>
    <origin rpy="0 0 0" xyz="0 0 0"/>
  </joint>
  <joint name="joint0" type="continuous">
    <parent link="link0"/>
    <child link="link1"/>
    <origin rpy="0 0 0" xyz="0.16661 0.10529 0.077"/>
    <axis xyz="0 0 0"/>
  </joint>
  <joint name="joint1" type="continuous">
    <parent link="link1"/>
    <child link="link2"/>
    <origin rpy="0 0 0" xyz="0.16661 -0.0037121 0.29901"/>
    <axis xyz="1 0 -1"/>
  </joint>
  <joint name="joint2" type="continuous">
    <parent link="link2"/>
    <child link="link3"/>
    <origin rpy="0 0 0" xyz="0.16661 0.026788 0.74901"/>
    <axis xyz="1 0 -1"/>
  </joint>
  <joint name="joint3" type="continuous">
    <parent link="link3"/>
    <child link="link4"/>
    <origin rpy="0 0 0" xyz="0.16661 0.10179 1.016"/>
    <axis xyz="0 0 0"/>
  </joint>
  <joint name="joint4" type="continuous">
    <parent link="link4"/>
    <child link="link5"/>
    <origin rpy="0 0 0" xyz="0.16661 -0.012212 1.099"/>
    <axis xyz="1 0 -1"/>
  </joint>
  <joint name="joint5" type="continuous">
    <parent link="link5"/>
    <child link="link6"/>
    <origin rpy="0 0 0" xyz="0.16661 -0.081212 1.267"/>
    <axis xyz="0 0 0"/>
  </joint>
  <joint name="tcp" type="fixed">
    <parent link="link6"/>
    <child link="tcp"/>
    <origin rpy="0 0 0" xyz="0 0 0.06"/>
  </joint>
</robot>
